Workbook

Sheet Registro y Control Mensual
B2: 📝 REGISTRO Y AUDITORÍA MENSUAL DE CUENTAS — DIEGO & SOLEDAD
B3: Pestaña activa al entrar: ingresen aquí las boletas pagadas del mes. Al lado ven el presupuesto real y el semáforo avisa si varió demasiado.
B4: 🗓️ MES EN AUDITORÍA: | D4: Octubre 2026 (En Curso) | F4: 📅 FECHA ACTUALIZACIÓN: | H4: 26/10/2026 | I4: 🟢 Estado: Mes Abierto | K4: 💡 Al terminar: duplica la hoja para archivar
B6: PRESUPUESTO META HOGAR | D6: ✏️ REAL MES ACTIVO | F6: DESVÍO NETO HOGAR | H6: SEMÁFORO DEL MES | J6: EXCEDENTE LIBRE FAMILIAR
B7: ='Dashboard Resumen'!D31 | D7: =G42 | F7: =G42-F42 | H7: =IF(G42=0,"⚪ Pendiente", IF((G42-F42)>25000,"🔴 Desvío Total Alto", IF((G42-F42)>10000,"🟡 Alerta Moderada", IF((G42-F42)<-10000,"💎 Superávit Hogar","🟢 En Presupuesto")))) | J7: ='Dashboard Resumen'!E31-(G42-F42)
B8: Plan base mensual acordado | D8: Total boletas ingresadas | F8: Diferencia acumulada vs meta | H8: Diagnóstico de variación | J8: Capacidad de ahorro real del hogar
B10: TABLA DE INGRESO MENSUAL: COMPARATIVA VS META Y SEMÁFORO DE VARIACIÓN
B11: # | C11: Categoría | D11: Concepto / Servicio | E11: Resp. | F11: Presupuesto Meta | G11: ✏️ Real Mes Activo | H11: Diferencia ($) | I11: Variación (%) | J11: Semáforo / Alerta | K11: Promedio 14 Meses | L11: Notas / Causa de Variación
B12: 1 | C12: Vivienda | D12: Crédito Hipotecario (Base en UF) | E12: Diego | F12: 360000 | G12: 360181 | H12: =IF(OR(G12="",G12=0),"-", G12-IF(F12="",0,F12)) | I12: =IF(OR(G12="",F12="",F12=0),"-", IFERROR((G12-F12)/F12, 0)) | J12: =IF(OR(G12="",G12=0),"-", IF(H12>15000,"🔴 Desvío Fuerte", IF(I12>0.08,"🟡 Alerta (+8%)", IF(H12<-5000,"💎 Ahorro","🟢 En Rango")))) | K12: 354730 | L12: Alza gradual según valor UF
B13: 2 | C13: Vivienda Huasco | D13: Arriendo Habitación Huasco | E13: Diego | F13: 95000 | G13: 95000 | H13: =IF(OR(G13="",G13=0),"-", G13-IF(F13="",0,F13)) | I13: =IF(OR(G13="",F13="",F13=0),"-", IFERROR((G13-F13)/F13, 0)) | J13: =IF(OR(G13="",G13=0),"-", IF(H13>15000,"🔴 Desvío Fuerte", IF(I13>0.08,"🟡 Alerta (+8%)", IF(H13<-5000,"💎 Ahorro","🟢 En Rango")))) | K13: 95000 | L13: Costo fijo mensual
B14: 3 | C14: Vivienda Huasco | D14: Servicios Huasco (Luz y Agua) | E14: Diego | F14: 7000 | G14: 7000 | H14: =IF(OR(G14="",G14=0),"-", G14-IF(F14="",0,F14)) | I14: =IF(OR(G14="",F14="",F14=0),"-", IFERROR((G14-F14)/F14, 0)) | J14: =IF(OR(G14="",G14=0),"-", IF(H14>15000,"🔴 Desvío Fuerte", IF(I14>0.08,"🟡 Alerta (+8%)", IF(H14<-5000,"💎 Ahorro","🟢 En Rango")))) | K14: 7000 | L14: Promedio constante
B15: 4 | C15: Conectividad | D15: Internet + Planes Celular (Diego) | E15: Diego | F15: 40000 | G15: 40000 | H15: =IF(OR(G15="",G15=0),"-", G15-IF(F15="",0,F15)) | I15: =IF(OR(G15="",F15="",F15=0),"-", IFERROR((G15-F15)/F15, 0)) | J15: =IF(OR(G15="",G15=0),"-", IF(H15>15000,"🔴 Desvío Fuerte", IF(I15>0.08,"🟡 Alerta (+8%)", IF(H15<-5000,"💎 Ahorro","🟢 En Rango")))) | K15: 40000 | L15: Fijo recurrente
B16: 5 | C16: Mascotas | D16: Comida Michis | E16: Diego | F16: 42000 | G16: 42000 | H16: =IF(OR(G16="",G16=0),"-", G16-IF(F16="",0,F16)) | I16: =IF(OR(G16="",F16="",F16=0),"-", IFERROR((G16-F16)/F16, 0)) | J16: =IF(OR(G16="",G16=0),"-", IF(H16>15000,"🔴 Desvío Fuerte", IF(I16>0.08,"🟡 Alerta (+8%)", IF(H16<-5000,"💎 Ahorro","🟢 En Rango")))) | K16: 42200 | L16: Asumido por Diego (~$40k-$42k)
B17: 6 | C17: Mascotas | D17: Arena Sanitaria Michis | E17: Diego | F17: 20000 | G17: 20000 | H17: =IF(OR(G17="",G17=0),"-", G17-IF(F17="",0,F17)) | I17: =IF(OR(G17="",F17="",F17=0),"-", IFERROR((G17-F17)/F17, 0)) | J17: =IF(OR(G17="",G17=0),"-", IF(H17>15000,"🔴 Desvío Fuerte", IF(I17>0.08,"🟡 Alerta (+8%)", IF(H17<-5000,"💎 Ahorro","🟢 En Rango")))) | K17: 20163 | L17: Compra mensual/bimestral
B18: 7 | C18: Streaming | D18: Netflix | E18: Diego | F18: 10388 | G18: 10388 | H18: =IF(OR(G18="",G18=0),"-", G18-IF(F18="",0,F18)) | I18: =IF(OR(G18="",F18="",F18=0),"-", IFERROR((G18-F18)/F18, 0)) | J18: =IF(OR(G18="",G18=0),"-", IF(H18>15000,"🔴 Desvío Fuerte", IF(I18>0.08,"🟡 Alerta (+8%)", IF(H18<-5000,"💎 Ahorro","🟢 En Rango")))) | K18: 10388 | L18: Tarifa fija recurrente
B19: 8 | C19: Streaming | D19: Crunchyroll | E19: Diego | F19: 6490 | G19: 6490 | H19: =IF(OR(G19="",G19=0),"-", G19-IF(F19="",0,F19)) | I19: =IF(OR(G19="",F19="",F19=0),"-", IFERROR((G19-F19)/F19, 0)) | J19: =IF(OR(G19="",G19=0),"-", IF(H19>15000,"🔴 Desvío Fuerte", IF(I19>0.08,"🟡 Alerta (+8%)", IF(H19<-5000,"💎 Ahorro","🟢 En Rango")))) | K19: 6490 | L19: Tarifa fija recurrente
B20: 9 | C20: Salud Cíclica | D20: Eutirox 137 | E20: Diego | F20: 10000 | G20: 10000 | H20: =IF(OR(G20="",G20=0),"-", G20-IF(F20="",0,F20)) | I20: =IF(OR(G20="",F20="",F20=0),"-", IFERROR((G20-F20)/F20, 0)) | J20: =IF(OR(G20="",G20=0),"-", IF(H20>15000,"🔴 Desvío Fuerte", IF(I20>0.08,"🟡 Alerta (+8%)", IF(H20<-5000,"💎 Ahorro","🟢 En Rango")))) | K20: 10000 | L20: Ajuste mensual medicamento
B21: 10 | C21: Salud Cíclica | D21: Rupatadina | E21: Diego | F21: 10382 | G21: 10382 | H21: =IF(OR(G21="",G21=0),"-", G21-IF(F21="",0,F21)) | I21: =IF(OR(G21="",F21="",F21=0),"-", IFERROR((G21-F21)/F21, 0)) | J21: =IF(OR(G21="",G21=0),"-", IF(H21>15000,"🔴 Desvío Fuerte", IF(I21>0.08,"🟡 Alerta (+8%)", IF(H21<-5000,"💎 Ahorro","🟢 En Rango")))) | K21: 10382 | L21: Ajuste mensual medicamento
B22: 11 | C22: Operaciones | D22: Pasajes Interregionales (8 viajes) | E22: Diego | F22: 231500 | G22: 231500 | H22: =IF(OR(G22="",G22=0),"-", G22-IF(F22="",0,F22)) | I22: =IF(OR(G22="",F22="",F22=0),"-", IFERROR((G22-F22)/F22, 0)) | J22: =IF(OR(G22="",G22=0),"-", IF(H22>15000,"🔴 Desvío Fuerte", IF(I22>0.08,"🟡 Alerta (+8%)", IF(H22<-5000,"💎 Ahorro","🟢 En Rango")))) | K22: 231500 | L22: Descuentos en pasajes
B23: 12 | C23: Operaciones | D23: Uber (Traslados y retenciones) | E23: Diego | F23: 25000 | G23: 25000 | H23: =IF(OR(G23="",G23=0),"-", G23-IF(F23="",0,F23)) | I23: =IF(OR(G23="",F23="",F23=0),"-", IFERROR((G23-F23)/F23, 0)) | J23: =IF(OR(G23="",G23=0),"-", IF(H23>15000,"🔴 Desvío Fuerte", IF(I23>0.08,"🟡 Alerta (+8%)", IF(H23<-5000,"💎 Ahorro","🟢 En Rango")))) | K23: 25000 | L23: Margen PayU
... B27: 16 | C27: Ahorro | D27: Fondo Emergencia Mercado Pago | E27: Diego | F27: 130000 | G27: 130000 | H27: =IF(OR(G27="",G27=0),"-", G27-IF(F27="",0,F27)) | I27: =IF(OR(G27="",F27="",F27=0),"-", IFERROR((G27-F27)/F27, 0)) | J27: =IF(OR(G27="",G27=0),"-", IF(H27>15000,"🔴 Desvío Fuerte", IF(I27>0.08,"🟡 Alerta (+8%)", IF(H27<-5000,"💎 Ahorro","🟢 En Rango")))) | K27: 130000 | L27: Ahorro constante mensual
B28: 17 | C28: Varios Diego | D28: [ + Escribir nuevo gasto Diego ] | E28: Diego | H28: =IF(OR(G28="",G28=0),"-", G28-IF(F28="",0,F28)) | I28: =IF(OR(G28="",F28="",F28=0),"-", IFERROR((G28-F28)/F28, 0)) | J28: =IF(OR(G28="",G28=0),"-", IF(H28>15000,"🔴 Desvío Fuerte", IF(I28>0.08,"🟡 Alerta (+8%)", IF(H28<-5000,"💎 Ahorro","🟢 En Rango")))) | L28: Fila libre para nuevo ítem
B29: 18 | C29: Varios Diego | D29: [ + Escribir nuevo gasto Diego ] | E29: Diego | H29: =IF(OR(G29="",G29=0),"-", G29-IF(F29="",0,F29)) | I29: =IF(OR(G29="",F29="",F29=0),"-", IFERROR((G29-F29)/F29, 0)) | J29: =IF(OR(G29="",G29=0),"-", IF(H29>15000,"🔴 Desvío Fuerte", IF(I29>0.08,"🟡 Alerta (+8%)", IF(H29<-5000,"💎 Ahorro","🟢 En Rango")))) | L29: Fila libre para nuevo ítem
B30: SUBTOTAL DIEGO (Cuenta Fan + Tenpo + Mach + MP) | F30: =SUM(F12:F29) | G30: =SUM(G12:G29) | H30: =G30-F30 | I30: =IFERROR((G30-F30)/F30, 0) | J30: =IF(H30>20000,"🔴 Desvío Diego", IF(I30>0.05,"🟡 Alerta Diego","🟢 En Presupuesto")) | K30: =SUM(K12:K29) | L30: Compromisos asignados a Diego
B31: 19 | C31: Hogar Limache | D31: Luz (CGE / Chilquinta) | E31: Soledad | F31: 22500 | G31: 23762 | H31: =IF(OR(G31="",G31=0),"-", G31-IF(F31="",0,F31)) | I31: =IF(OR(G31="",F31="",F31=0),"-", IFERROR((G31-F31)/F31, 0)) | J31: =IF(OR(G31="",G31=0),"-", IF(H31>15000,"🔴 Desvío Fuerte", IF(I31>0.08,"🟡 Alerta (+8%)", IF(H31<-5000,"💎 Ahorro","🟢 En Rango")))) | K31: 22220 | L31: Promedio real histórico 14 meses
B32: 20 | C32: Hogar Limache | D32: Agua (Esval) | E32: Soledad | F32: 7200 | G32: 7840 | H32: =IF(OR(G32="",G32=0),"-", G32-IF(F32="",0,F32)) | I32: =IF(OR(G32="",F32="",F32=0),"-", IFERROR((G32-F32)/F32, 0)) | J32: =IF(OR(G32="",G32=0),"-", IF(H32>15000,"🔴 Desvío Fuerte", IF(I32>0.08,"🟡 Alerta (+8%)", IF(H32<-5000,"💎 Ahorro","🟢 En Rango")))) | K32: 7134 | L32: Consumo estable (~$7.1k)
B33: 21 | C33: Hogar Limache | D33: Gas (Lipigas / Abastible) | E33: Soledad | F33: 20500 | G33: 25500 | H33: =IF(OR(G33="",G33=0),"-", G33-IF(F33="",0,F33)) | I33: =IF(OR(G33="",F33="",F33=0),"-", IFERROR((G33-F33)/F33, 0)) | J33: =IF(OR(G33="",G33=0),"-", IF(H33>15000,"🔴 Desvío Fuerte", IF(I33>0.08,"🟡 Alerta (+8%)", IF(H33<-5000,"💎 Ahorro","🟢 En Rango")))) | K33: 20114 | L33: Invierno $25k-$30k / Verano $15k
B34: 22 | C34: Conectividad | D34: Plan Claro (Pareja) | E34: Soledad | F34: 9500 | G34: 9600 | H34: =IF(OR(G34="",G34=0),"-", G34-IF(F34="",0,F34)) | I34: =IF(OR(G34="",F34="",F34=0),"-", IFERROR((G34-F34)/F34, 0)) | J34: =IF(OR(G34="",G34=0),"-", IF(H34>15000,"🔴 Desvío Fuerte", IF(I34>0.08,"🟡 Alerta (+8%)", IF(H34<-5000,"💎 Ahorro","🟢 En Rango")))) | K34: 9372 | L34: Tarifa plan móvil pareja
B35: 23 | C35: Hogar Limache | D35: Gasto Común Condominio | E35: Soledad | F35: 52500 | G35: 56315 | H35: =IF(OR(G35="",G35=0),"-", G35-IF(F35="",0,F35)) | I35: =IF(OR(G35="",F35="",F35=0),"-", IFERROR((G35-F35)/F35, 0)) | J35: =IF(OR(G35="",G35=0),"-", IF(H35>15000,"🔴 Desvío Fuerte", IF(I35>0.08,"🟡 Alerta (+8%)", IF(H35<-5000,"💎 Ahorro","🟢 En Rango")))) | K35: 52539 | L35: Promedio histórico real
B36: 24 | C36: Alimentación | D36: Supermercado Hogar Limache | E36: Soledad | F36: 125000 | G36: 120000 | H36: =IF(OR(G36="",G36=0),"-", G36-IF(F36="",0,F36)) | I36: =IF(OR(G36="",F36="",F36=0),"-", IFERROR((G36-F36)/F36, 0)) | J36: =IF(OR(G36="",G36=0),"-", IF(H36>15000,"🔴 Desvío Fuerte", IF(I36>0.08,"🟡 Alerta (+8%)", IF(H36<-5000,"💎 Ahorro","🟢 En Rango")))) | K36: 127196 | L36: Presupuesto asignado hogar
B37: 25 | C37: Hogar Limache | D37: Aseo Domiciliario (Cuota Municipal) | E37: Soledad | F37: 4550 | G37: 4614 | H37: =IF(OR(G37="",G37=0),"-", G37-IF(F37="",0,F37)) | I37: =IF(OR(G37="",F37="",F37=0),"-", IFERROR((G37-F37)/F37, 0)) | J37: =IF(OR(G37="",G37=0),"-", IF(H37>15000,"🔴 Desvío Fuerte", IF(I37>0.08,"🟡 Alerta (+8%)", IF(H37<-5000,"💎 Ahorro","🟢 En Rango")))) | K37: 4550 | L37: Aporte mensual ($13.6k trimestral)
B38: 26 | C38: Compromisos | D38: Tarjeta Smart Visa (Compromiso) | E38: Soledad | F38: 50000 | G38: 50000 | H38: =IF(OR(G38="",G38=0),"-", G38-IF(F38="",0,F38)) | I38: =IF(OR(G38="",F38="",F38=0),"-", IFERROR((G38-F38)/F38, 0)) | J38: =IF(OR(G38="",G38=0),"-", IF(H38>15000,"🔴 Desvío Fuerte", IF(I38>0.08,"🟡 Alerta (+8%)", IF(H38<-5000,"💎 Ahorro","🟢 En Rango")))) | K38: 45951 | L38: Promedio real cuota mensual
B39: 27 | C39: Varios Soledad | D39: [ + Escribir nuevo gasto Soledad ] | E39: Soledad | H39: =IF(OR(G39="",G39=0),"-", G39-IF(F39="",0,F39)) | I39: =IF(OR(G39="",F39="",F39=0),"-", IFERROR((G39-F39)/F39, 0)) | J39: =IF(OR(G39="",G39=0),"-", IF(H39>15000,"🔴 Desvío Fuerte", IF(I39>0.08,"🟡 Alerta (+8%)", IF(H39<-5000,"💎 Ahorro","🟢 En Rango")))) | L39: Fila libre para nuevo ítem
B40: 28 | C40: Varios Soledad | D40: [ + Escribir nuevo gasto Soledad ] | E40: Soledad | H40: =IF(OR(G40="",G40=0),"-", G40-IF(F40="",0,F40)) | I40: =IF(OR(G40="",F40="",F40=0),"-", IFERROR((G40-F40)/F40, 0)) | J40: =IF(OR(G40="",G40=0),"-", IF(H40>15000,"🔴 Desvío Fuerte", IF(I40>0.08,"🟡 Alerta (+8%)", IF(H40<-5000,"💎 Ahorro","🟢 En Rango")))) | L40: Fila libre para nuevo ítem
B41: SUBTOTAL SOLEDAD (Hogar Limache + Tarjeta Smart) | F41: =SUM(F31:F40) | G41: =SUM(G31:G40) | H41: =G41-F41 | I41: =IFERROR((G41-F41)/F41, 0) | J41: =IF(H41>15000,"🔴 Desvío Soledad", IF(I41>0.05,"🟡 Alerta Soledad","🟢 En Presupuesto")) | K41: =SUM(K31:K40) | L41: Compromisos asignados a Soledad
B42: GRAN TOTAL CONSOLIDADO HOGAR | F42: =F30+F41 | G42: =G30+G41 | H42: =G42-F42 | I42: =IFERROR((G42-F42)/F42, 0) | J42: =IF(H42>25000,"🔴 Desvío Total Alto", IF(H42>10000,"🟡 Alerta Moderada", IF(H42<-10000,"💎 Superávit Hogar","🟢 En Presupuesto"))) | K42: =K30+K41 | L42: Seguimiento integral mensual pareja
B44: 💡 GUÍA FÁCIL: ¿CÓMO USAR Y AGREGAR NUEVOS GASTOS EN ESTA PLANILLA?
B45: • Solo ingresen el monto en la columna amarilla (✏️ Real Mes Activo). No toquen otras columnas para no borrar fórmulas.
B46: • Para agregar un nuevo gasto: escriban directamente en las filas libres '[ + Escribir nuevo gasto... ]'. Ya están calculadas en los subtotales.

Sheet Dashboard Resumen
B2: 📊 PANEL DE CONTROL FINANCIERO CONSOLIDADO — HOGAR DIEGO & SOLEDAD
B3: Presupuesto familiar sincronizado • Diego ($1.214.038 | 58.1%) & Soledad ($875.000 | 41.9%) • Total Hogar: $2.089.038
B5: INGRESOS FAMILIARES | D5: GASTOS TOTALES HOGAR | F5: AHORRO BLINDADO MES | H5: COLCHÓN OXÍGENO DIEGO | J5: MARGEN LIBRE SOLEDAD | L5: SUPERÁVIT TOTAL HOGAR
B6: ='Control Gastos'!E13 | D6: ='Control Gastos'!E53 | F6: ='Control Gastos'!E38 | H6: =C29-D29 | J6: =C30-D30 | L6: =C31-D31
B7: Diego ($1.214k) + Soledad ($875k) | D7: Fijos + Operaciones + Limache | F7: Mercado Pago (Rendimiento diario) | H7: Margen de seguridad libre Diego | J7: Capacidad libre mensual Soledad | L7: 30.0% tasa de ahorro libre del hogar
B9: 1. APORTES & ESTRUCTURA DE INGRESOS FAMILIARES
B10: Integrante | C10: % Aporte | D10: Cuenta de Abono | E10: Monto Base (CLP) | F10: Destino / Misión
B11: Diego | C11: ='Control Gastos'!G11 | D11: Cuenta Corriente / Vista | E11: ='Control Gastos'!E11 | F11: Vivienda, Operaciones Huasco y Ahorro
B12: Soledad | C12: ='Control Gastos'!G12 | D12: Chequera BancoEstado | E12: ='Control Gastos'!E12 | F12: Cuentas Hogar Limache y Smart Visa
B13: TOTAL INGRESO FAMILIAR | D13: 100.0% | E13: =SUM(E11:E12) | F13: Ingreso neto mensual del hogar
B16: 2. ASIGNACIÓN MENSUAL POR COFRE & CUENTA BANCARIA
B17: Cofre / Destino | C17: Responsable | D17: Cuenta / Medio | E17: Monto Mensual | F17: % del Ingreso
B18: Vivienda & Gastos Fijos Diego | C18: Diego | D18: Cuenta Fan | E18: ='Control Gastos'!E25 | F18: =IFERROR(E18/$E$13, 0)
B19: Operaciones & Logística Huasco | C19: Diego | D19: Tenpo Prepago | E19: ='Control Gastos'!E33 | F19: =IFERROR(E19/$E$13, 0)
B20: Bolsillo Personal (Modo Recuperación) | C20: Diego | D20: Mach | E20: ='Control Gastos'!E37 | F20: =IFERROR(E20/$E$13, 0)
B21: Ahorro Blindado / Fondo Reserva | C21: Diego | D21: Mercado Pago | E21: ='Control Gastos'!E38 | F21: =IFERROR(E21/$E$13, 0)
B22: Gastos Hogar & Cuentas Básicas | C22: Soledad | D22: Chequera BancoEstado | E22: =SUM('Control Gastos'!E43:E49) | F22: =IFERROR(E22/$E$13, 0)
B23: Tarjeta Smart Visa (Compromiso Pareja) | C23: Soledad | D23: BancoEstado | E23: ='Control Gastos'!E50 | F23: =IFERROR(E23/$E$13, 0)
B24: TOTAL GASTOS & COMPROMISOS HOGAR | E24: =SUM(E18:E23) | F24: =SUM(F18:F23)
B27: 3. BALANCES & CAPACIDAD LIBRE REAL POR INTEGRANTE
B28: Integrante | C28: Ingreso Líquido | D28: Compromisos Asignados | E28: Margen / Capacidad Libre | F28: Tasa de Ahorro / Margen
B29: Diego | C29: =E11 | D29: =SUM(E18:E21) | E29: =C29-D29 | F29: =IFERROR(E29/C29, 0)
B30: Soledad | C30: =E12 | D30: =SUM(E22:E23) | E30: =C30-D30 | F30: =IFERROR(E30/C30, 0)
B31: TOTAL HOGAR | C31: =SUM(C29:C30) | D31: =SUM(D29:D30) | E31: =SUM(E29:E30) | F31: =IFERROR(E31/C31, 0)

Sheet Historico 2024-2025
B2: 📈 HISTÓRICO REAL DE CUENTAS DEL HOGAR — 14 MESES (AGOSTO 2024 A SEPTIEMBRE 2025)
B3: Base de datos empírica para calibrar presupuestos, detectar estacionalidad (invierno/verano) y monitorear alzas de UF e IPC.
B5: # | C5: Categoría | D5: Concepto / Servicio | E5: Resp. | F5: Ago-24 | G5: Sep-24 | H5: Oct-24 | I5: Nov-24 | J5: Dic-24 | K5: Ene-25 | L5: Feb-25 | M5: Mar-25 | N5: Abr-25 | O5: May-25 | P5: Jun-25 | Q5: Jul-25 | R5: Ago-25 | S5: Sep-25 | T5: Promedio Real | U5: Comportamiento / Estacionalidad
B6: 1 | C6: Hogar Limache | D6: Luz (Chilquinta) | E6: Soledad | F6: 53251 | G6: 22486 | H6: 12930 | I6: 14081 | J6: 12496 | K6: 12597 | L6: 16010 | M6: 15512 | N6: 18206 | O6: 17641 | P6: 23359 | Q6: 40631 | R6: 28122 | S6: 23762 | T6: =AVERAGE(F6:S6) | U6: Picos en invierno ($53k Ago-24, $40k Jul-25); Verano ~$12k-$16k
B7: 2 | C7: Hogar Limache | D7: Agua (Esval) | E7: Soledad | F7: 7610 | G7: 7280 | H7: 6370 | I7: 6470 | J7: 6420 | K7: 6440 | L7: 7160 | M7: 8030 | N7: 7140 | O7: 8020 | P7: 7134 | Q7: 6230 | R7: 7870 | S7: 7840 | T7: =AVERAGE(F7:S7) | U7: Consumo muy parejo todo el año: entre $6.2k y $8.0k
B8: 3 | C8: Hogar Limache | D8: Gas (Balón / Red) | E8: Soledad | F8: 28550 | G8: 19500 | H8: 19850 | I8: 15250 | J8: 15750 | K8: 15850 | L8: 15900 | M8: 11350 | N8: 21100 | O8: 20900 | P8: 20950 | Q8: 20850 | R8: 30300 | S8: 25500 | T8: =AVERAGE(F8:S8) | U8: Estacionalidad invernal marcada ($25k-$30k); Verano baja a $11k-$15k
B9: 4 | C9: Conectividad | D9: Plan Claro (Pareja) | E9: Soledad | F9: 9150 | G9: 9150 | H9: 9208 | I9: 9208 | J9: 9329 | K9: 9329 | L9: 9329 | M9: 9429 | N9: 9434 | O9: 9434 | P9: 9537 | Q9: 9539 | R9: 9537 | S9: 9600 | T9: =AVERAGE(F9:S9) | U9: Ajuste suave por IPC; muy predecible
B10: 5 | C10: Hogar Limache | D10: Gasto Común Condominio | E10: Soledad | F10: 47000 | G10: 51000 | H10: 52723 | I10: 49748 | J10: 51273 | K10: 52426 | L10: 58696 | M10: 54132 | N10: 46904 | O10: 53670 | P10: 53476 | Q10: 53571 | R10: 54606 | S10: 56315 | T10: =AVERAGE(F10:S10) | U10: Rango entre $47k y $58k; promedio consolidado $52.5k
B11: 6 | C11: Mascotas | D11: Comida Michis | E11: Diego | F11: 40000 | G11: 40000 | I11: 40000 | K11: 46000 | M11: 39900 | O11: 40000 | P11: 40000 | R11: 51700 | T11: =AVERAGE(F11:S11) | U11: Compras en sacos grandes (mes por medio); promedio mensual ~$42k
B12: 7 | C12: Mascotas | D12: Arena Sanitaria Michis | E12: Diego | F12: 20000 | G12: 20000 | I12: 20000 | J12: 28000 | K12: 20000 | M12: 17900 | N12: 17900 | O12: 17990 | P12: 20000 | R12: 20000 | S12: 20000 | T12: =AVERAGE(F12:S12) | U12: Consumo mensual regular de ~$18k-$20k
B13: 8 | C13: Mascotas | D13: Vacunas Michis (Eventual) | E13: Diego | F13: 45000 | G13: 45000 | S13: 57000 | T13: =AVERAGE(F13:S13) | U13: Gastos médicos anuales (antirrábica + leucemia)
B14: 9 | C14: Vivienda | D14: Crédito Hipotecario (UF) | E14: Diego | I14: 346506 | J14: 348108 | K14: 350320 | L14: 352707 | M14: 354930 | N14: 356679 | O14: 357554 | P14: 358261 | Q14: 357433 | R14: 359354 | S14: 360181 | T14: =AVERAGE(F14:S14) | U14: Inició en $346k (Nov-24) y subió a $360k (Sep-25) por valor UF
B15: 10 | C15: Compromisos | D15: Tarjeta Smart Visa | E15: Soledad | M15: 54640 | P15: 23815 | Q15: 52304 | R15: 48994 | S15: 50000 | T15: =AVERAGE(F15:S15) | U15: Cuota mensual promedio real de ~$50k
B16: 11 | C16: Hogar Limache | D16: Aseo Domiciliario Municipal | E16: Soledad | N16: 13600 | P16: 13538 | S16: 13841 | T16: =AVERAGE(F16:S16) | U16: Pago trimestral municipal (~$4.5k mensual prorrateado)
B17: 12 | C17: Educación / Otros | D17: Curso Waldorf / Proyector | E17: Ambos | F17: 50000 | G17: 50000 | H17: 97000 | I17: 50000 | J17: 50000 | K17: 50000 | T17: =AVERAGE(F17:S17) | U17: Compromisos temporales 2024-2025 ya finalizados o amortizados
B18: 13 | C18: Alimentación | D18: Supermercado Hogar Limache | E18: Soledad | J18: 50000 | N18: 126000 | O18: 153000 | P18: 109782 | T18: =AVERAGE(F18:S18) | U18: Registros puntuales; promedio mensual calibrado en $125k
B19: TOTAL CUENTAS REGISTRADAS DEL HOGAR | F19: =SUM(F6:F18) | G19: =SUM(G6:G18) | H19: =SUM(H6:H18) | I19: =SUM(I6:I18) | J19: =SUM(J6:J18) | K19: =SUM(K6:K18) | L19: =SUM(L6:L18) | M19: =SUM(M6:M18) | ... S19: =SUM(S6:S18) | T19: =AVERAGE(T6:T18) | U19: Evolución histórica consolidada

Sheet Control Gastos
B2: 📋 PRESUPUESTO MAESTRO & MATRIZ DE ASIGNACIÓN — DIEGO & SOLEDAD
B3: Parámetros base mensuales acordados y calibrados según los 14 meses de registros reales.
B5: 1. INGRESOS MENSUALES LÍQUIDOS (BASE MAESTRA)
B6: # | C6: Integrante | D6: Concepto de Renta | E6: Monto Líquido | F6: Medio de Depósito | G6: % del Total | H6: Frecuencia | I6: Notas
B11: 1 | C11: Diego | D11: Sueldo Líquido Diego | E11: 1214038 | F11: Transferencia Banco | G11: =IFERROR(E11/$E$13, 0) | H11: Mensual | I11: Renta líquida contractual
B12: 2 | C12: Soledad | D12: Sueldo Líquido Soledad (Promedio) | E12: 875000 | F12: Chequera BancoEstado | G12: =IFERROR(E12/$E$13, 0) | H12: Mensual | I12: Rango $850.000 - $900.000
B13: TOTAL INGRESOS HOGAR | E13: =SUM(E11:E12) | G13: =SUM(G11:G12) | I13: =E13
B15: 2. VIVIENDA & GASTOS FIJOS — DIEGO (CUENTA FAN)
B16: # | C16: Categoría | D16: Concepto | E16: Monto Base | F16: Medio | G16: % Ingreso | H16: Frecuencia | I16: Notas
B17: 1 | C17: Vivienda | D17: Crédito Hipotecario (UF) | E17: 360000 | F17: Cuenta Fan | G17: =IFERROR(E17/$E$13, 0) | H17: Mensual | I17: Alza gradual UF
B18: 2 | C18: Vivienda Huasco | D18: Arriendo Habitación Huasco | E18: 95000 | F18: Cuenta Fan | G18: =IFERROR(E18/$E$13, 0) | H18: Mensual | I18: Contrato vigente
B19: 3 | C19: Vivienda Huasco | D19: Servicios Huasco (Luz y Agua) | E19: 7000 | F19: Cuenta Fan | G19: =IFERROR(E19/$E$13, 0) | H19: Mensual | I19: Tarifa fija
B20: 4 | C20: Conectividad | D20: Internet + Celular (Diego) | E20: 40000 | F20: Cuenta Fan | G20: =IFERROR(E20/$E$13, 0) | H20: Mensual | I20: Plan fijo
B21: 5 | C21: Mascotas | D21: Comida Michis | E21: 42000 | F21: Cuenta Fan | G21: =IFERROR(E21/$E$13, 0) | H21: Mensual | I21: Promedio 14 meses
B22: 6 | C22: Mascotas | D22: Arena Sanitaria Michis | E22: 20000 | F22: Cuenta Fan | G22: =IFERROR(E22/$E$13, 0) | H22: Mensual | I22: Promedio 14 meses
B23: 7 | C23: Streaming | D23: Netflix + Crunchyroll | E23: 16878 | F23: Cuenta Fan | G23: =IFERROR(E23/$E$13, 0) | H23: Mensual | I23: $10.388 + $6.490
B24: 8 | C24: Salud | D24: Eutirox 137 + Rupatadina | E24: 20382 | F24: Cuenta Fan | G24: =IFERROR(E24/$E$13, 0) | H24: Mensual | I24: $10.000 + $10.382
B25: SUBTOTAL VIVIENDA & FIJOS DIEGO | E25: =SUM(E17:E24) | G25: =SUM(G17:G24)
B27: 3. OPERACIONES & LOGÍSTICA HUASCO — DIEGO (TENPO)
B28: # | C28: Categoría | D28: Concepto | E28: Monto Base | F28: Medio | G28: % Ingreso | H28: Frecuencia | I28: Notas
B29: 9 | C29: Operaciones | D29: Pasajes Interregionales (8 tramos) | E29: 231500 | F29: Tenpo | G29: =IFERROR(E29/$E$13, 0) | H29: Mensual | I29: Pasajes Huasco
B30: 10 | C30: Operaciones | D30: Uber (Traslados y retenciones) | E30: 25000 | F30: Tenpo | G30: =IFERROR(E30/$E$13, 0) | H30: Mensual | I30: Margen PayU
B31: 11 | C31: Operaciones | D31: Metro Valparaíso (EFE) | E31: 10000 | F31: Tenpo | G31: =IFERROR(E31/$E$13, 0) | H31: Mensual | I31: Recargas
B32: 12 | C32: Operaciones | D32: Snacks Turno (Galletas + Energéticas) | E32: 33500 | F32: Tenpo | G32: =IFERROR(E32/$E$13, 0) | H32: Mensual | I32: Consumo en turno
B33: SUBTOTAL OPERACIONES TENPO | E33: =SUM(E29:E32) | G33: =SUM(G29:G32)
B35: 4. BOLSILLO PERSONAL & AHORRO BLINDADO — DIEGO (MACH & MERCADO PAGO)
B36: # | C36: Categoría | D36: Concepto | E36: Monto Base | F36: Medio | G36: % Ingreso | H36: Frecuencia | I36: Notas
B37: 13 | C37: Bolsillo | D37: Asignación Semanal Mach ($35k x 4) | E37: 140000 | F37: Mach | G37: =IFERROR(E37/$E$13, 0) | H37: Semanal | I37: Modo recuperación
B38: 14 | C38: Ahorro | D38: Fondo Emergencia Mercado Pago | E38: 130000 | F38: Mercado Pago | G38: =IFERROR(E38/$E$13, 0) | H38: Mensual | I38: Rendimiento diario
B39: SUBTOTAL BOLSILLO & AHORRO DIEGO | E39: =SUM(E37:E38) | G39: =SUM(G37:G38)
B41: 5. CUENTAS BÁSICAS LIMACHE & COMPROMISOS — SOLEDAD (BANCOESTADO)
B42: # | C42: Categoría | D42: Concepto | E42: Monto Base | F42: Medio | G42: % Ingreso | H42: Frecuencia | I42: Notas
B43: 15 | C43: Hogar Limache | D43: Luz (CGE / Chilquinta) | E43: 22500 | F43: BancoEstado | G43: =IFERROR(E43/$E$13, 0) | H43: Mensual | I43: Promedio 14 meses ($22.2k)
B44: 16 | C44: Hogar Limache | D44: Agua (Esval) | E44: 7200 | F44: BancoEstado | G44: =IFERROR(E44/$E$13, 0) | H44: Mensual | I44: Promedio 14 meses ($7.1k)
B45: 17 | C45: Hogar Limache | D45: Gas (Lipigas / Abastible) | E45: 20500 | F45: BancoEstado | G45: =IFERROR(E45/$E$13, 0) | H45: Mensual | I45: Promedio 14 meses ($20.1k)
B46: 18 | C46: Conectividad | D46: Plan Claro (Pareja) | E46: 9500 | F46: BancoEstado | G46: =IFERROR(E46/$E$13, 0) | H46: Mensual | I46: Promedio 14 meses ($9.3k)
B47: 19 | C47: Hogar Limache | D47: Gasto Común Condominio | E47: 52500 | F47: BancoEstado | G47: =IFERROR(E47/$E$13, 0) | H47: Mensual | I47: Promedio 14 meses ($52.5k)
B48: 20 | C48: Alimentación | D48: Supermercado Hogar Limache | E48: 125000 | F48: BancoEstado | G48: =IFERROR(E48/$E$13, 0) | H48: Mensual | I48: Presupuesto promedio acordado
B49: 21 | C49: Hogar Limache | D49: Aseo Domiciliario Municipal | E49: 4550 | F49: BancoEstado | G49: =IFERROR(E49/$E$13, 0) | H49: Mensual | I49: Cuota trimestral $13.6k
B50: 22 | C50: Compromisos | D50: Tarjeta Smart Visa | E50: 50000 | F50: BancoEstado | G50: =IFERROR(E50/$E$13, 0) | H50: Mensual | I50: Promedio 14 meses (~$46k-$50k)
...

Sheet Simulador Crecimiento
B2: 🚀 SIMULADOR DE ALZA DE RENTA & CRONOGRAMA DE BLINDAJE
B3: Plan para la meta de $2.100.000 en Mercado Pago (3 meses de gastos) y optimización de futuros incrementos de sueldo.
B5: CRONOGRAMA DE ACELERACIÓN DEL FONDO DE EMERGENCIA ($2.100.000)
B6: Mes / Hito | C6: Aporte Diego (MP) | D6: Aporte Soledad (Opcional) | E6: Interés Diario (~6%) | F6: Total Ahorro Mes | G6: Saldo Acumulado | H6: % Meta Alcanzada
B7: Mes 1 (Inicio) | C7: 130000 | D7: 200000 | E7: 3000 | F7: =C7+D7+E7 | G7: =600000+F7 | H7: =IFERROR(G7/2100000, 0)
B8: Mes 2 | C8: 130000 | D8: 200000 | E8: 4600 | F8: =C8+D8+E8 | G8: =G7+F8 | H8: =IFERROR(G8/2100000, 0)
B9: Mes 3 | C9: 130000 | D9: 200000 | E9: 6300 | F9: =C9+D9+E9 | G9: =G8+F9 | H9: =IFERROR(G9/2100000, 0)
B10: Mes 4 (Meta Cumplida) | C10: 130000 | D10: 200000 | E10: 8000 | F10: =C10+D10+E10 | G10: =G9+F10 | H10: =IFERROR(G10/2100000, 0)
B11: Mes 5 (Fondo Blindado) | C11: 130000 | D11: 100000 | E11: 10500 | F11: =C11+D11+E11 | G11: =G10+F11 | H11: =IFERROR(G11/2100000, 0)

Sheet Guia de Uso
B2: 📘 GUÍA PASO A PASO: USO EN PC Y GOOGLE SHEETS DESDE EL CELULAR
B3: Instrucciones claras y sin complicaciones para ingresar datos y entender cada número.
B5: 1. ¿CÓMO INGRESAR LAS BOLETAS DEL MES?
B6: • Abre la primera pestaña 'Registro y Control Mensual'.
B7: • SOLO debes escribir en la columna amarilla ('✏️ Real Mes Activo'). No toques las otras columnas.
B8: • Si pagaron la Luz por $23.500, escribe 23500 en la fila de Luz.
B9: • Si no tienen el valor de una boleta todavía, déjala en blanco. El sistema la marcará como pendiente.
B11: 2. ¿CÓMO ENTENDER LOS SEMÁFOROS Y DESVÍOS?
B12: • 🟢 Verde ('En Rango'): La cuenta llegó normal, dentro de lo esperado. ¡Todo bien!
B13: • 🟡 Amarillo ('Alerta +8%'): La cuenta subió un poquito sobre el promedio (más de $5.000). Atentos.
B14: • 🔴 Rojo ('Desvío Fuerte'): Subió más de $15.000 (típico en la Luz en invierno). Revisar la boleta.
B15: • 💎 Diamante ('Ahorro'): Pagaron menos de lo presupuestado. ¡Quedó plata a favor del hogar!
... B26: • En iPhone: En Safari, toca Compartir > 'Agregar al inicio'. Tendrán un icono como una app en el celular.
